[2022-01-30 01:35:49,577] {taskinstance.py:1032} INFO - Dependencies all met for <TaskInstance: data_ingestion_gcs_dag_fhv_2.download_dataset_task scheduled__2021-12-02T06:00:00+00:00 [queued]>
[2022-01-30 01:35:49,667] {taskinstance.py:1032} INFO - Dependencies all met for <TaskInstance: data_ingestion_gcs_dag_fhv_2.download_dataset_task scheduled__2021-12-02T06:00:00+00:00 [queued]>
[2022-01-30 01:35:49,669] {taskinstance.py:1238} INFO - 
--------------------------------------------------------------------------------
[2022-01-30 01:35:49,669] {taskinstance.py:1239} INFO - Starting attempt 1 of 1
[2022-01-30 01:35:49,677] {taskinstance.py:1240} INFO - 
--------------------------------------------------------------------------------
[2022-01-30 01:35:49,753] {taskinstance.py:1259} INFO - Executing <Task(BashOperator): download_dataset_task> on 2021-12-02 06:00:00+00:00
[2022-01-30 01:35:49,819] {standard_task_runner.py:52} INFO - Started process 1326 to run task
[2022-01-30 01:35:49,847] {standard_task_runner.py:76} INFO - Running: ['***', 'tasks', 'run', 'data_ingestion_gcs_dag_fhv_2', 'download_dataset_task', 'scheduled__2021-12-02T06:00:00+00:00', '--job-id', '157', '--raw', '--subdir', 'DAGS_FOLDER/data_ingestion_gcs_dag_2_fhv.py', '--cfg-path', '/tmp/tmpzw0aji27', '--error-file', '/tmp/tmplqwrml_g']
[2022-01-30 01:35:49,870] {standard_task_runner.py:77} INFO - Job 157: Subtask download_dataset_task
[2022-01-30 01:35:50,409] {logging_mixin.py:109} INFO - Running <TaskInstance: data_ingestion_gcs_dag_fhv_2.download_dataset_task scheduled__2021-12-02T06:00:00+00:00 [running]> on host 04ca2676bdcc
[2022-01-30 01:35:50,775] {warnings.py:110} WARNING - /home/***/.local/lib/python3.7/site-packages/***/utils/context.py:152: AirflowContextDeprecationWarning: Accessing 'execution_date' from the template is deprecated and will be removed in a future version. Please use 'data_interval_start' or 'logical_date' instead.
  warnings.warn(_create_deprecation_warning(key, self._deprecation_replacements[key]))

[2022-01-30 01:35:50,886] {taskinstance.py:1426} INFO - Exporting the following env vars:
AIRFLOW_CTX_DAG_OWNER=***
AIRFLOW_CTX_DAG_ID=data_ingestion_gcs_dag_fhv_2
AIRFLOW_CTX_TASK_ID=download_dataset_task
AIRFLOW_CTX_EXECUTION_DATE=2021-12-02T06:00:00+00:00
AIRFLOW_CTX_DAG_RUN_ID=scheduled__2021-12-02T06:00:00+00:00
[2022-01-30 01:35:50,887] {subprocess.py:62} INFO - Tmp dir root location: 
 /tmp
[2022-01-30 01:35:50,904] {subprocess.py:74} INFO - Running command: ['bash', '-c', 'curl -sSLf https://nyc-tlc.s3.amazonaws.com/trip+data/fhv_tripdata_2021-12.csv > /opt/***/fhv_tripdata_2021-12.csv']
[2022-01-30 01:35:50,951] {subprocess.py:85} INFO - Output:
[2022-01-30 01:35:51,427] {subprocess.py:89} INFO - curl: (22) The requested URL returned error: 404 Not Found
[2022-01-30 01:35:51,428] {subprocess.py:93} INFO - Command exited with return code 22
[2022-01-30 01:35:51,471] {taskinstance.py:1700} ERROR - Task failed with exception
Traceback (most recent call last):
  File "/home/airflow/.local/lib/python3.7/site-packages/airflow/models/taskinstance.py", line 1329, in _run_raw_task
    self._execute_task_with_callbacks(context)
  File "/home/airflow/.local/lib/python3.7/site-packages/airflow/models/taskinstance.py", line 1455, in _execute_task_with_callbacks
    result = self._execute_task(context, self.task)
  File "/home/airflow/.local/lib/python3.7/site-packages/airflow/models/taskinstance.py", line 1511, in _execute_task
    result = execute_callable(context=context)
  File "/home/airflow/.local/lib/python3.7/site-packages/airflow/operators/bash.py", line 188, in execute
    f'Bash command failed. The command returned a non-zero exit code {result.exit_code}.'
airflow.exceptions.AirflowException: Bash command failed. The command returned a non-zero exit code 22.
[2022-01-30 01:35:51,502] {taskinstance.py:1277} INFO - Marking task as FAILED. dag_id=data_ingestion_gcs_dag_fhv_2, task_id=download_dataset_task, execution_date=20211202T060000, start_date=20220130T013549, end_date=20220130T013551
[2022-01-30 01:35:51,570] {standard_task_runner.py:92} ERROR - Failed to execute job 157 for task download_dataset_task
Traceback (most recent call last):
  File "/home/airflow/.local/lib/python3.7/site-packages/airflow/task/task_runner/standard_task_runner.py", line 85, in _start_by_fork
    args.func(args, dag=self.dag)
  File "/home/airflow/.local/lib/python3.7/site-packages/airflow/cli/cli_parser.py", line 48, in command
    return func(*args, **kwargs)
  File "/home/airflow/.local/lib/python3.7/site-packages/airflow/utils/cli.py", line 92, in wrapper
    return f(*args, **kwargs)
  File "/home/airflow/.local/lib/python3.7/site-packages/airflow/cli/commands/task_command.py", line 298, in task_run
    _run_task_by_selected_method(args, dag, ti)
  File "/home/airflow/.local/lib/python3.7/site-packages/airflow/cli/commands/task_command.py", line 107, in _run_task_by_selected_method
    _run_raw_task(args, ti)
  File "/home/airflow/.local/lib/python3.7/site-packages/airflow/cli/commands/task_command.py", line 184, in _run_raw_task
    error_file=args.error_file,
  File "/home/airflow/.local/lib/python3.7/site-packages/airflow/utils/session.py", line 70, in wrapper
    return func(*args, session=session, **kwargs)
  File "/home/airflow/.local/lib/python3.7/site-packages/airflow/models/taskinstance.py", line 1329, in _run_raw_task
    self._execute_task_with_callbacks(context)
  File "/home/airflow/.local/lib/python3.7/site-packages/airflow/models/taskinstance.py", line 1455, in _execute_task_with_callbacks
    result = self._execute_task(context, self.task)
  File "/home/airflow/.local/lib/python3.7/site-packages/airflow/models/taskinstance.py", line 1511, in _execute_task
    result = execute_callable(context=context)
  File "/home/airflow/.local/lib/python3.7/site-packages/airflow/operators/bash.py", line 188, in execute
    f'Bash command failed. The command returned a non-zero exit code {result.exit_code}.'
airflow.exceptions.AirflowException: Bash command failed. The command returned a non-zero exit code 22.
[2022-01-30 01:35:51,604] {local_task_job.py:154} INFO - Task exited with return code 1
[2022-01-30 01:35:51,674] {local_task_job.py:264} INFO - 0 downstream tasks scheduled from follow-on schedule check
